<?xml version="1.0" encoding="UTF-8"?>
<!-- Generated by org.testng.reporters.JUnitReportReporter -->
<testsuite hostname="DESKTOP-PRI1S77" failures="4" tests="4" name="DataDrivenTesting.createNewUser" time="17.946" errors="0" timestamp="2021-02-14T21:17:26 IST" skipped="0">
  <testcase classname="DataDrivenTesting.createNewUser" name="createuser" time="4.489">
    <failure message="expected:&lt;201&gt; but was:&lt;204&gt;" type="junit.framework.AssertionFailedError">
      <![CDATA[junit.framework.AssertionFailedError: expected:<201> but was:<204>
at junit.framework.Assert.fail(Assert.java:50)
at junit.framework.Assert.failNotEquals(Assert.java:287)
at junit.framework.Assert.assertEquals(Assert.java:67)
at junit.framework.Assert.assertEquals(Assert.java:199)
at junit.framework.Assert.assertEquals(Assert.java:205)
at DataDrivenTesting.validationSuite.validateStatusCode(validationSuite.java:18)
at DataDrivenTesting.createNewUser.createuser(createNewUser.java:42)
at java.base/jdk.internal.reflect.NativeMethodAccessorImpl.invoke0(Native Method)
at java.base/jdk.internal.reflect.NativeMethodAccessorImpl.invoke(NativeMethodAccessorImpl.java:62)
at java.base/jdk.internal.reflect.DelegatingMethodAccessorImpl.invoke(DelegatingMethodAccessorImpl.java:43)
at java.base/java.lang.reflect.Method.invoke(Method.java:567)
at org.testng.internal.MethodInvocationHelper.invokeMethod(MethodInvocationHelper.java:132)
at org.testng.internal.TestInvoker.invokeMethod(TestInvoker.java:599)
at org.testng.internal.TestInvoker.invokeTestMethod(TestInvoker.java:174)
at org.testng.internal.TestMethodWithDataProviderMethodWorker.call(TestMethodWithDataProviderMethodWorker.java:77)
at org.testng.internal.TestMethodWithDataProviderMethodWorker.call(TestMethodWithDataProviderMethodWorker.java:15)
at java.base/java.util.concurrent.FutureTask.run(FutureTask.java:264)
at java.base/java.util.concurrent.Executors$RunnableAdapter.call(Executors.java:515)
at java.base/java.util.concurrent.FutureTask.run(FutureTask.java:264)
at java.base/java.util.concurrent.ThreadPoolExecutor.runWorker(ThreadPoolExecutor.java:1128)
at java.base/java.util.concurrent.ThreadPoolExecutor$Worker.run(ThreadPoolExecutor.java:628)
at java.base/java.lang.Thread.run(Thread.java:830)
]]>
    </failure>
  </testcase> <!-- createuser -->
  <system-out/>
  <testcase classname="DataDrivenTesting.createNewUser" name="createuser" time="4.486">
    <failure message="expected:&lt;201&gt; but was:&lt;204&gt;" type="junit.framework.AssertionFailedError">
      <![CDATA[junit.framework.AssertionFailedError: expected:<201> but was:<204>
at junit.framework.Assert.fail(Assert.java:50)
at junit.framework.Assert.failNotEquals(Assert.java:287)
at junit.framework.Assert.assertEquals(Assert.java:67)
at junit.framework.Assert.assertEquals(Assert.java:199)
at junit.framework.Assert.assertEquals(Assert.java:205)
at DataDrivenTesting.validationSuite.validateStatusCode(validationSuite.java:18)
at DataDrivenTesting.createNewUser.createuser(createNewUser.java:42)
at java.base/jdk.internal.reflect.NativeMethodAccessorImpl.invoke0(Native Method)
at java.base/jdk.internal.reflect.NativeMethodAccessorImpl.invoke(NativeMethodAccessorImpl.java:62)
at java.base/jdk.internal.reflect.DelegatingMethodAccessorImpl.invoke(DelegatingMethodAccessorImpl.java:43)
at java.base/java.lang.reflect.Method.invoke(Method.java:567)
at org.testng.internal.MethodInvocationHelper.invokeMethod(MethodInvocationHelper.java:132)
at org.testng.internal.TestInvoker.invokeMethod(TestInvoker.java:599)
at org.testng.internal.TestInvoker.invokeTestMethod(TestInvoker.java:174)
at org.testng.internal.TestMethodWithDataProviderMethodWorker.call(TestMethodWithDataProviderMethodWorker.java:77)
at org.testng.internal.TestMethodWithDataProviderMethodWorker.call(TestMethodWithDataProviderMethodWorker.java:15)
at java.base/java.util.concurrent.FutureTask.run(FutureTask.java:264)
at java.base/java.util.concurrent.Executors$RunnableAdapter.call(Executors.java:515)
at java.base/java.util.concurrent.FutureTask.run(FutureTask.java:264)
at java.base/java.util.concurrent.ThreadPoolExecutor.runWorker(ThreadPoolExecutor.java:1128)
at java.base/java.util.concurrent.ThreadPoolExecutor$Worker.run(ThreadPoolExecutor.java:628)
at java.base/java.lang.Thread.run(Thread.java:830)
]]>
    </failure>
  </testcase> <!-- createuser -->
  <system-out/>
  <testcase classname="DataDrivenTesting.createNewUser" name="createuser" time="4.486">
    <failure message="expected:&lt;201&gt; but was:&lt;204&gt;" type="junit.framework.AssertionFailedError">
      <![CDATA[junit.framework.AssertionFailedError: expected:<201> but was:<204>
at junit.framework.Assert.fail(Assert.java:50)
at junit.framework.Assert.failNotEquals(Assert.java:287)
at junit.framework.Assert.assertEquals(Assert.java:67)
at junit.framework.Assert.assertEquals(Assert.java:199)
at junit.framework.Assert.assertEquals(Assert.java:205)
at DataDrivenTesting.validationSuite.validateStatusCode(validationSuite.java:18)
at DataDrivenTesting.createNewUser.createuser(createNewUser.java:42)
at java.base/jdk.internal.reflect.NativeMethodAccessorImpl.invoke0(Native Method)
at java.base/jdk.internal.reflect.NativeMethodAccessorImpl.invoke(NativeMethodAccessorImpl.java:62)
at java.base/jdk.internal.reflect.DelegatingMethodAccessorImpl.invoke(DelegatingMethodAccessorImpl.java:43)
at java.base/java.lang.reflect.Method.invoke(Method.java:567)
at org.testng.internal.MethodInvocationHelper.invokeMethod(MethodInvocationHelper.java:132)
at org.testng.internal.TestInvoker.invokeMethod(TestInvoker.java:599)
at org.testng.internal.TestInvoker.invokeTestMethod(TestInvoker.java:174)
at org.testng.internal.TestMethodWithDataProviderMethodWorker.call(TestMethodWithDataProviderMethodWorker.java:77)
at org.testng.internal.TestMethodWithDataProviderMethodWorker.call(TestMethodWithDataProviderMethodWorker.java:15)
at java.base/java.util.concurrent.FutureTask.run(FutureTask.java:264)
at java.base/java.util.concurrent.Executors$RunnableAdapter.call(Executors.java:515)
at java.base/java.util.concurrent.FutureTask.run(FutureTask.java:264)
at java.base/java.util.concurrent.ThreadPoolExecutor.runWorker(ThreadPoolExecutor.java:1128)
at java.base/java.util.concurrent.ThreadPoolExecutor$Worker.run(ThreadPoolExecutor.java:628)
at java.base/java.lang.Thread.run(Thread.java:830)
]]>
    </failure>
  </testcase> <!-- createuser -->
  <system-out/>
  <testcase classname="DataDrivenTesting.createNewUser" name="createuser" time="4.485">
    <failure message="expected:&lt;201&gt; but was:&lt;204&gt;" type="junit.framework.AssertionFailedError">
      <![CDATA[junit.framework.AssertionFailedError: expected:<201> but was:<204>
at junit.framework.Assert.fail(Assert.java:50)
at junit.framework.Assert.failNotEquals(Assert.java:287)
at junit.framework.Assert.assertEquals(Assert.java:67)
at junit.framework.Assert.assertEquals(Assert.java:199)
at junit.framework.Assert.assertEquals(Assert.java:205)
at DataDrivenTesting.validationSuite.validateStatusCode(validationSuite.java:18)
at DataDrivenTesting.createNewUser.createuser(createNewUser.java:42)
at java.base/jdk.internal.reflect.NativeMethodAccessorImpl.invoke0(Native Method)
at java.base/jdk.internal.reflect.NativeMethodAccessorImpl.invoke(NativeMethodAccessorImpl.java:62)
at java.base/jdk.internal.reflect.DelegatingMethodAccessorImpl.invoke(DelegatingMethodAccessorImpl.java:43)
at java.base/java.lang.reflect.Method.invoke(Method.java:567)
at org.testng.internal.MethodInvocationHelper.invokeMethod(MethodInvocationHelper.java:132)
at org.testng.internal.TestInvoker.invokeMethod(TestInvoker.java:599)
at org.testng.internal.TestInvoker.invokeTestMethod(TestInvoker.java:174)
at org.testng.internal.TestMethodWithDataProviderMethodWorker.call(TestMethodWithDataProviderMethodWorker.java:77)
at org.testng.internal.TestMethodWithDataProviderMethodWorker.call(TestMethodWithDataProviderMethodWorker.java:15)
at java.base/java.util.concurrent.FutureTask.run(FutureTask.java:264)
at java.base/java.util.concurrent.Executors$RunnableAdapter.call(Executors.java:515)
at java.base/java.util.concurrent.FutureTask.run(FutureTask.java:264)
at java.base/java.util.concurrent.ThreadPoolExecutor.runWorker(ThreadPoolExecutor.java:1128)
at java.base/java.util.concurrent.ThreadPoolExecutor$Worker.run(ThreadPoolExecutor.java:628)
at java.base/java.lang.Thread.run(Thread.java:830)
]]>
    </failure>
  </testcase> <!-- createuser -->
  <system-out/>
</testsuite> <!-- DataDrivenTesting.createNewUser -->
